try:
    print(1/0)
except:
    print("An exception occured")
finally:
  print("The 'try except' is finished")